<?xml version="1.0"?>

<robot name="threeDOF">
  
  <!-- *************************************************** -->
  <!-- ******************** Kinematics ******************* -->
  <!-- *************************************************** -->
  <!-- Note the 'origin' tag in the joints defines the
       shift and reorientation before the continuous joint
       rotates around the 'axis'. -->

  <link name="world"/>

  <joint name="theta1" type="prismatic">
    <parent link="world"/>
    <child  link="tip"/>
    <origin xyz="0 0 0" rpy="0 0 0"/>
    <limit effort="1000.0" lower="-2.5" upper="2.5" velocity="0.5"/>
    <axis   xyz="0 0 1"/>
  </joint>

  <link name="tip"/>


  <!-- *************************************************** -->
  <!-- ********************* Graphics ******************** -->
  <!-- *************************************************** -->
  <!-- The following is purely to make this look roboticy. -->
  <!-- The 'origin' tag in the link/visual defines the
       center of the object (box, cylinder, sphere, mesh)
       but does not affect the joint chain kinematics. -->

  <!-- *************** Materials / Colors **************** -->

  <material name="white">    <color rgba="1.00 1.00 1.00 1"/>  </material>
  <material name="gray">     <color rgba="0.60 0.60 0.60 1"/>  </material>
  <material name="table">    <color rgba="0.85 0.77 0.77 1"/>  </material>
  <material name="black">    <color rgba="0.00 0.00 0.00 1"/>  </material>

  <material name="red">      <color rgba="1.00 0.00 0.00 1"/>  </material>
  <material name="green">    <color rgba="0.00 1.00 0.00 1"/>  </material>
  <material name="blue">     <color rgba="0.00 0.00 1.00 1"/>  </material>

  <material name="cyan">     <color rgba="0.00 1.00 1.00 1"/>  </material>
  <material name="magenta">  <color rgba="1.00 0.00 1.00 1"/>  </material>
  <material name="yellow">   <color rgba="1.00 1.00 0.00 1"/>  </material>

  <material name="orange">   <color rgba="1.00 0.65 0.00 1"/>  </material>


  <!-- *** Table - attached to world *** -->

  <!-- <joint name="attach-table" type="fixed">
    <parent link="world"/>
    <child  link="table"/>
  </joint>

  <link name="table">
    <visual>
      <origin xyz="0 0 -0.425" rpy="0 0 0"/>
      <geometry>
	<box size="1.0 1.0 0.05"/>
      </geometry>
      <material name="table"/>
    </visual>
  </link> -->

</robot>
