<?xml version="1.0"?>

<robot name="stewart">
  
  <!-- *************************************************** -->
  <!-- ******************** Kinematics ******************* -->
  <!-- *************************************************** -->
  <!-- Note the 'origin' tag in the joints defines the
       shift and reorientation before the continuous joint
       rotates around the 'axis'. -->

  <link name="world"/>


  <joint name="theta1" type="continuous">
    <parent link="world"/>
    <child  link="link1"/>
    <origin xyz="0 1.25 -0.2" rpy="0 0 0"/>
    <axis   xyz="1 0 0"/>
  </joint>

  <link name="link1"/>

  <joint name="theta2" type="continuous">
    <parent link="link1"/>
    <child  link="link2"/>
    <origin xyz="0 0 0" rpy="0 0 0"/>
    <axis   xyz="0 1 0"/>
  </joint>

  <link name="link2"/>

  <joint name="d3" type="prismatic">
    <parent link="link2"/>
    <child  link="link3"/>
    <origin xyz="0 0 -0.4" rpy="0 0 0"/>
    <limit effort="1000.0" lower="0" upper="1.5" velocity="0.5"/>
    <axis   xyz="0 0 -1"/>
  </joint>

  <link name="link3"/>

  <joint name="shifttotip" type="fixed">
    <parent link="link3"/>
    <child  link="tip"/>
    <origin xyz="0 0 0" rpy="0 0 0"/>
  </joint>

  <link name="tip"/>

  <!-- <link name="platform4">

  <link name="platform5">

  <link name="platform6"> -->


  <!-- *************************************************** -->
  <!-- ********************* Graphics ******************** -->
  <!-- *************************************************** -->
  <!-- The following is purely to make this look roboticy. -->
  <!-- The 'origin' tag in the link/visual defines the
       center of the object (box, cylinder, sphere, mesh)
       but does not affect the joint chain kinematics. -->

  <!-- *************** Materials / Colors **************** -->

  <material name="white">    <color rgba="1.00 1.00 1.00 1"/>  </material>
  <material name="gray">     <color rgba="0.60 0.60 0.60 1"/>  </material>
  <material name="table">    <color rgba="0.85 0.77 0.77 1"/>  </material>
  <material name="black">    <color rgba="0.00 0.00 0.00 1"/>  </material>

  <material name="red">      <color rgba="1.00 0.00 0.00 1"/>  </material>
  <material name="green">    <color rgba="0.00 1.00 0.00 1"/>  </material>
  <material name="blue">     <color rgba="0.00 0.00 1.00 1"/>  </material>

  <material name="cyan">     <color rgba="0.00 1.00 1.00 1"/>  </material>
  <material name="magenta">  <color rgba="1.00 0.00 1.00 1"/>  </material>
  <material name="yellow">   <color rgba="1.00 1.00 0.00 1"/>  </material>

  <material name="orange">   <color rgba="1.00 0.65 0.00 1"/>  </material>


  <!-- *** Table - attached to world *** -->

  <joint name="attach-top" type="fixed">
    <parent link="world"/>
    <child  link="top"/>
  </joint>

  <link name="top">
    <visual>
      <origin rpy="3.14159 0 0" xyz="0 0 0"/>
      <geometry>
        <mesh filename="package://finalprojectcode/meshes/Platform_Top.dae"/>
      </geometry>
    </visual>
  </link>


  <joint name="attach-joint1" type="fixed">
    <parent link="link1"/>
    <child  link="uj-shaft"/>
  </joint>

  <link name="uj-shaft">
    <visual>
      <origin rpy="0 0 0" xyz="0 0 0"/>
      <geometry>
        <mesh filename="package://finalprojectcode/meshes/UJ_Shaft.dae"/>
      </geometry>
    </visual>
  </link>

  <joint name="attach-joint2" type="fixed">
    <parent link="link2"/>
    <child  link="slider-base"/>
  </joint>

  <link name="slider-base">
    <visual>
      <origin rpy="3.14159 0 0" xyz="0 0 0"/>
      <geometry>
        <mesh filename="package://finalprojectcode/meshes/Slider_Base.dae"/>
      </geometry>
    </visual>
  </link>

<joint name="attach-joint3" type="fixed">
    <parent link="link3"/>
    <child  link="slider-shaft"/>
  </joint>

  <link name="slider-shaft">
    <visual>
      <origin rpy="3.14159 0 0" xyz="0 0 0"/>
      <geometry>
        <mesh filename="package://finalprojectcode/meshes/Slider_Shaft.dae"/>
      </geometry>
    </visual>
  </link>

</robot>
